2024-12-14 04:34:10,596 INFO    MainThread:50090 [wandb_setup.py:_flush():68] Current SDK version is 0.19.1
2024-12-14 04:34:10,596 INFO    MainThread:50090 [wandb_setup.py:_flush():68] Configure stats pid to 50090
2024-12-14 04:34:10,596 INFO    MainThread:50090 [wandb_setup.py:_flush():68] Loading settings from /app/.config/wandb/settings
2024-12-14 04:34:10,597 INFO    MainThread:50090 [wandb_setup.py:_flush():68] Loading settings from /root/app/wandb/settings
2024-12-14 04:34:10,597 INFO    MainThread:50090 [wandb_setup.py:_flush():68] Loading settings from environment variables
2024-12-14 04:34:10,597 INFO    MainThread:50090 [wandb_init.py:_log_setup():528] Logging user logs to /root/app/wandb/run-20241214_043410-5jx81miw/logs/debug.log
2024-12-14 04:34:10,598 INFO    MainThread:50090 [wandb_init.py:_log_setup():529] Logging internal logs to /root/app/wandb/run-20241214_043410-5jx81miw/logs/debug-internal.log
2024-12-14 04:34:10,598 INFO    MainThread:50090 [wandb_init.py:init():644] calling init triggers
2024-12-14 04:34:10,598 INFO    MainThread:50090 [wandb_init.py:init():650] wandb.init called with sweep_config: {}
config: {}
2024-12-14 04:34:10,598 INFO    MainThread:50090 [wandb_init.py:init():680] starting backend
2024-12-14 04:34:10,598 INFO    MainThread:50090 [wandb_init.py:init():684] sending inform_init request
2024-12-14 04:34:10,630 INFO    MainThread:50090 [backend.py:_multiprocessing_setup():104] multiprocessing start_methods=fork,spawn,forkserver, using: spawn
2024-12-14 04:34:10,630 INFO    MainThread:50090 [wandb_init.py:init():697] backend started and connected
2024-12-14 04:34:10,632 INFO    MainThread:50090 [wandb_init.py:init():790] updated telemetry
2024-12-14 04:34:10,689 INFO    MainThread:50090 [wandb_init.py:init():822] communicating run to backend with 90.0 second timeout
2024-12-14 04:34:11,073 ERROR   MainThread:50090 [wandb_init.py:init():849] encountered error: failed to upsert bucket: returned error 403 Forbidden: {"errors":[{"message":"permission denied","path":["upsertBucket"],"extensions":{"code":"PERMISSION_ERROR"}}],"data":{"upsertBucket":null}}
2024-12-14 04:34:11,073 ERROR   MainThread:50090 [wandb_init.py:init():1308] error in wandb.init()
Traceback (most recent call last):
  File "/root/app/.venv/lib/python3.11/site-packages/wandb/sdk/wandb_init.py", line 1298, in init
    return wi.init()
           ^^^^^^^^^
  File "/root/app/.venv/lib/python3.11/site-packages/wandb/sdk/wandb_init.py", line 855, in init
    raise error
wandb.errors.errors.CommError: failed to upsert bucket: returned error 403 Forbidden: {"errors":[{"message":"permission denied","path":["upsertBucket"],"extensions":{"code":"PERMISSION_ERROR"}}],"data":{"upsertBucket":null}}
2024-12-14 04:34:11,098 WARNING MsgRouterThr:50090 [router.py:message_loop():75] message_loop has been closed
